wandb: logging graph, to disable use `wandb.watch(log_graph=False)`
data_cfg.trajdata_predict_types ['vehicle']
{'cache_location': '~/my_custom_cache_location', 'desired_data': ['nusc_trainval-train', 'nusc_trainval-train_val'], 'desired_dt': 0.1, 'future_sec': (5.2, 5.2), 'history_sec': (3.0, 3.0), 'data_dirs': <configs.custom_config.ConfigBase object at 0x70c6bf3cdc40>, 'only_types': [<AgentType.VEHICLE: 1>], 'only_predict': [<AgentType.VEHICLE: 1>], 'agent_interaction_distances': defaultdict(<function PassUnifiedDataModule.setup.<locals>.<lambda> at 0x70c6b46e4f70>, {}), 'incl_raster_map': True, 'raster_map_params': {'px_per_m': 2, 'map_size_px': 224, 'return_rgb': False, 'offset_frac_xy': [-0.5, 0.0], 'no_map_fill_value': -1.0}, 'incl_vector_map': True, 'centric': 'agent', 'scene_description_contains': None, 'standardize_data': True, 'verbose': True, 'max_agent_num': None, 'num_workers': 24, 'rebuild_cache': False, 'rebuild_maps': False, 'extras': {'closest_lane_point': <function get_closest_lane_point_wrapper.<locals>.get_closest_lane_point at 0x70c6b46e4e50>, 'full_fut_traj': <function get_full_fut_traj at 0x70c66ab511f0>, 'full_fut_valid': <function get_full_fut_valid at 0x70c66ab51280>}}
/home/visier/ctg_project/trajdata/src/trajdata/dataset_specific/nusc/nusc_dataset.py:62: UserWarning: Beware, nusc_test has no annotations!
  warnings.warn("Beware, nusc_test has no annotations!")
Loading data for matched scene tags: ['train-boston-nusc_trainval', 'train-singapore-nusc_trainval', 'boston-train_val-nusc_trainval', 'singapore-train_val-nusc_trainval']
Calculating Agent Data (Serially): 100%|##########| 700/700 [00:00<00:00, 139292.76it/s]
700 scenes in the scene index.
Creating Agent Data Index (24 CPUs): 100%|##########| 700/700 [00:00<00:00, 18083.24it/s]
Structuring Agent Data Index: 100%|##########| 700/700 [00:00<00:00, 75499.20it/s]
Loading data for matched scene tags: ['boston-val-nusc_trainval', 'singapore-val-nusc_trainval']
Calculating Agent Data (Serially): 100%|##########| 150/150 [00:00<00:00, 104596.11it/s]
150 scenes in the scene index.
Creating Agent Data Index (24 CPUs): 100%|##########| 150/150 [00:00<00:00, 16926.62it/s]
Structuring Agent Data Index: 100%|##########| 150/150 [00:00<00:00, 61838.57it/s]
Epoch 0:  54%|#####3    | 4000/7447 [15:31<13:22,  4.29it/s, v_num=75e4]Traceback (most recent call last):
  File "/home/visier/hazardforge/HazardForge/train.py", line 212, in <module>
    main(default_config, auto_remove_exp_dir=default_config.train.remove_exp_dir, debug=default_config.train.debug)
  File "/home/visier/hazardforge/HazardForge/train.py", line 182, in main
    trainer.fit(model=model, datamodule=datamodule)
  File "/home/visier/anaconda3/envs/hf/lib/python3.9/site-packages/pytorch_lightning/trainer/trainer.py", line 545, in fit
    call._call_and_handle_interrupt(
  File "/home/visier/anaconda3/envs/hf/lib/python3.9/site-packages/pytorch_lightning/trainer/call.py", line 44, in _call_and_handle_interrupt
    return trainer_fn(*args, **kwargs)
  File "/home/visier/anaconda3/envs/hf/lib/python3.9/site-packages/pytorch_lightning/trainer/trainer.py", line 581, in _fit_impl
    self._run(model, ckpt_path=ckpt_path)
  File "/home/visier/anaconda3/envs/hf/lib/python3.9/site-packages/pytorch_lightning/trainer/trainer.py", line 990, in _run
    results = self._run_stage()
  File "/home/visier/anaconda3/envs/hf/lib/python3.9/site-packages/pytorch_lightning/trainer/trainer.py", line 1036, in _run_stage
    self.fit_loop.run()
  File "/home/visier/anaconda3/envs/hf/lib/python3.9/site-packages/pytorch_lightning/loops/fit_loop.py", line 202, in run
    self.advance()
  File "/home/visier/anaconda3/envs/hf/lib/python3.9/site-packages/pytorch_lightning/loops/fit_loop.py", line 359, in advance
    self.epoch_loop.run(self._data_fetcher)
  File "/home/visier/anaconda3/envs/hf/lib/python3.9/site-packages/pytorch_lightning/loops/training_epoch_loop.py", line 136, in run
    self.advance(data_fetcher)
  File "/home/visier/anaconda3/envs/hf/lib/python3.9/site-packages/pytorch_lightning/loops/training_epoch_loop.py", line 259, in advance
    call._call_callback_hooks(trainer, "on_train_batch_end", batch_output, batch, batch_idx)
  File "/home/visier/anaconda3/envs/hf/lib/python3.9/site-packages/pytorch_lightning/trainer/call.py", line 208, in _call_callback_hooks
    fn(trainer, trainer.lightning_module, *args, **kwargs)
  File "/home/visier/anaconda3/envs/hf/lib/python3.9/site-packages/pytorch_lightning/callbacks/model_checkpoint.py", line 303, in on_train_batch_end
    self._save_topk_checkpoint(trainer, monitor_candidates)
  File "/home/visier/anaconda3/envs/hf/lib/python3.9/site-packages/pytorch_lightning/callbacks/model_checkpoint.py", line 366, in _save_topk_checkpoint
    raise MisconfigurationException(m)
lightning_fabric.utilities.exceptions.MisconfigurationException: `ModelCheckpoint(monitor='val/ema_loss')` could not find the monitored key in the returned metrics: ['train/kl_loss', 'train/kl_loss_step', 'train/recon_loss', 'train/recon_loss_step', 'train/vae_loss', 'train/vae_loss_step', 'validation_loss', 'validation_loss_epoch', 'validation_reconstruction_loss', 'validation_reconstruction_loss_epoch', 'validation_kld_loss', 'validation_kld_loss_epoch', 'epoch', 'step']. HINT: Did you call `log('val/ema_loss', value)` in the `LightningModule`?
Traceback (most recent call last):
  File "/home/visier/hazardforge/HazardForge/train.py", line 212, in <module>
    main(default_config, auto_remove_exp_dir=default_config.train.remove_exp_dir, debug=default_config.train.debug)
  File "/home/visier/hazardforge/HazardForge/train.py", line 182, in main
    trainer.fit(model=model, datamodule=datamodule)
  File "/home/visier/anaconda3/envs/hf/lib/python3.9/site-packages/pytorch_lightning/trainer/trainer.py", line 545, in fit
    call._call_and_handle_interrupt(
  File "/home/visier/anaconda3/envs/hf/lib/python3.9/site-packages/pytorch_lightning/trainer/call.py", line 44, in _call_and_handle_interrupt
    return trainer_fn(*args, **kwargs)
  File "/home/visier/anaconda3/envs/hf/lib/python3.9/site-packages/pytorch_lightning/trainer/trainer.py", line 581, in _fit_impl
    self._run(model, ckpt_path=ckpt_path)
  File "/home/visier/anaconda3/envs/hf/lib/python3.9/site-packages/pytorch_lightning/trainer/trainer.py", line 990, in _run
    results = self._run_stage()
  File "/home/visier/anaconda3/envs/hf/lib/python3.9/site-packages/pytorch_lightning/trainer/trainer.py", line 1036, in _run_stage
    self.fit_loop.run()
  File "/home/visier/anaconda3/envs/hf/lib/python3.9/site-packages/pytorch_lightning/loops/fit_loop.py", line 202, in run
    self.advance()
  File "/home/visier/anaconda3/envs/hf/lib/python3.9/site-packages/pytorch_lightning/loops/fit_loop.py", line 359, in advance
    self.epoch_loop.run(self._data_fetcher)
  File "/home/visier/anaconda3/envs/hf/lib/python3.9/site-packages/pytorch_lightning/loops/training_epoch_loop.py", line 136, in run
    self.advance(data_fetcher)
  File "/home/visier/anaconda3/envs/hf/lib/python3.9/site-packages/pytorch_lightning/loops/training_epoch_loop.py", line 259, in advance
    call._call_callback_hooks(trainer, "on_train_batch_end", batch_output, batch, batch_idx)
  File "/home/visier/anaconda3/envs/hf/lib/python3.9/site-packages/pytorch_lightning/trainer/call.py", line 208, in _call_callback_hooks
    fn(trainer, trainer.lightning_module, *args, **kwargs)
  File "/home/visier/anaconda3/envs/hf/lib/python3.9/site-packages/pytorch_lightning/callbacks/model_checkpoint.py", line 303, in on_train_batch_end
    self._save_topk_checkpoint(trainer, monitor_candidates)
  File "/home/visier/anaconda3/envs/hf/lib/python3.9/site-packages/pytorch_lightning/callbacks/model_checkpoint.py", line 366, in _save_topk_checkpoint
    raise MisconfigurationException(m)
lightning_fabric.utilities.exceptions.MisconfigurationException: `ModelCheckpoint(monitor='val/ema_loss')` could not find the monitored key in the returned metrics: ['train/kl_loss', 'train/kl_loss_step', 'train/recon_loss', 'train/recon_loss_step', 'train/vae_loss', 'train/vae_loss_step', 'validation_loss', 'validation_loss_epoch', 'validation_reconstruction_loss', 'validation_reconstruction_loss_epoch', 'validation_kld_loss', 'validation_kld_loss_epoch', 'epoch', 'step']. HINT: Did you call `log('val/ema_loss', value)` in the `LightningModule`?
